Workbook

Sheet Dashboard
B2: CrowdFix Nepal — Requirements Traceability Matrix
B3: Live dashboard — auto-recomputes when the RTM sheet is updated
B5: OVERALL | E5: STATUS
B6: Total Requirements | C6: =COUNTA(RTM!A4:A51) -> 48 | E6: Not Started | F6: =COUNTIF(RTM!L4:L51,"Not Started") -> 12
B7: Functional (FR) | C7: =COUNTIF(RTM!A4:A51,"FR-*") -> 31 | E7: In Progress | F7: =COUNTIF(RTM!L4:L51,"In Progress") -> 2
B8: Non-Functional (NFR) | C8: =COUNTIF(RTM!A4:A51,"NFR-*") -> 17 | E8: Complete | F8: =COUNTIF(RTM!L4:L51,"Complete") -> 34
B9: High Priority | C9: =COUNTIF(RTM!D4:D51,"High") -> 30 | E9: Blocked | F9: =COUNTIF(RTM!L4:L51,"Blocked") -> 0
B10: Medium Priority | C10: =COUNTIF(RTM!D4:D51,"Medium") -> 14 | E10: Deferred | F10: =COUNTIF(RTM!L4:L51,"Deferred") -> 0
B11: Low Priority | C11: =COUNTIF(RTM!D4:D51,"Low") -> 4 | E11: % Complete | F11: =COUNTIF(RTM!L4:L51,"Complete")/COUNTA(RTM!A4:A51) -> 0.70833333
B14: BY OWNER
B15: Owner | C15: Total | D15: Complete | E15: % Done
B16: Pratik | C16: =COUNTIF(RTM!H4:H51,"*Pratik*") -> 35 | D16: =COUNTIFS(RTM!H4:H51,"*Pratik*",RTM!L4:L51,"Complete") -> 26 | E16: =IFERROR(D16/C16,0) -> 0.74285714
B17: Anjali | C17: =COUNTIF(RTM!H4:H51,"*Anjali*") -> 27 | D17: =COUNTIFS(RTM!H4:H51,"*Anjali*",RTM!L4:L51,"Complete") -> 23 | E17: =IFERROR(D17/C17,0) -> 0.85185185
B18: Dol Bahadur | C18: =COUNTIF(RTM!H4:H51,"*Dol Bahadur*") -> 8 | D18: =COUNTIFS(RTM!H4:H51,"*Dol Bahadur*",RTM!L4:L51,"Complete") -> 6 | E18: =IFERROR(D18/C18,0) -> 0.75
B19: Umang | C19: =COUNTIF(RTM!H4:H51,"*Umang*") -> 4 | D19: =COUNTIFS(RTM!H4:H51,"*Umang*",RTM!L4:L51,"Complete") -> 3 | E19: =IFERROR(D19/C19,0) -> 0.75
B22: BY BUILD PHASE
B23: Phase | C23: Total | D23: Complete | E23: % Done
B24: Phase 2 | C24: =COUNTIF(RTM!G4:G51,"*Phase 2*") -> 3 | D24: =COUNTIFS(RTM!G4:G51,"*Phase 2*",RTM!L4:L51,"Complete") -> 3 | E24: =IFERROR(D24/C24,0) -> 1
B25: Phase 3 | C25: =COUNTIF(RTM!G4:G51,"*Phase 3*") -> 1 | D25: =COUNTIFS(RTM!G4:G51,"*Phase 3*",RTM!L4:L51,"Complete") -> 1 | E25: =IFERROR(D25/C25,0) -> 1
B26: Phase 4 | C26: =COUNTIF(RTM!G4:G51,"*Phase 4*") -> 7 | D26: =COUNTIFS(RTM!G4:G51,"*Phase 4*",RTM!L4:L51,"Complete") -> 5 | E26: =IFERROR(D26/C26,0) -> 0.71428571
B27: Phase 7 | C27: =COUNTIF(RTM!G4:G51,"*Phase 7*") -> 5 | D27: =COUNTIFS(RTM!G4:G51,"*Phase 7*",RTM!L4:L51,"Complete") -> 4 | E27: =IFERROR(D27/C27,0) -> 0.8
B28: Phase 9 | C28: =COUNTIF(RTM!G4:G51,"*Phase 9*") -> 4 | D28: =COUNTIFS(RTM!G4:G51,"*Phase 9*",RTM!L4:L51,"Complete") -> 4 | E28: =IFERROR(D28/C28,0) -> 1
B29: Phase 10 | C29: =COUNTIF(RTM!G4:G51,"*Phase 10*") -> 6 | D29: =COUNTIFS(RTM!G4:G51,"*Phase 10*",RTM!L4:L51,"Complete") -> 4 | E29: =IFERROR(D29/C29,0) -> 0.66666667
B30: Phase 11 | C30: =COUNTIF(RTM!G4:G51,"*Phase 11*") -> 8 | D30: =COUNTIFS(RTM!G4:G51,"*Phase 11*",RTM!L4:L51,"Complete") -> 8 | E30: =IFERROR(D30/C30,0) -> 1
B31: Phase 12 | C31: =COUNTIF(RTM!G4:G51,"*Phase 12*") -> 1 | D31: =COUNTIFS(RTM!G4:G51,"*Phase 12*",RTM!L4:L51,"Complete") -> 1 | E31: =IFERROR(D31/C31,0) -> 1
B32: Phase 13 | C32: =COUNTIF(RTM!G4:G51,"*Phase 13*") -> 3 | D32: =COUNTIFS(RTM!G4:G51,"*Phase 13*",RTM!L4:L51,"Complete") -> 0 | E32: =IFERROR(D32/C32,0) -> 0
B33: Phase 14 | C33: =COUNTIF(RTM!G4:G51,"*Phase 14*") -> 1 | D33: =COUNTIFS(RTM!G4:G51,"*Phase 14*",RTM!L4:L51,"Complete") -> 0 | E33: =IFERROR(D33/C33,0) -> 0
B34: Phase 15 | C34: =COUNTIF(RTM!G4:G51,"*Phase 15*") -> 5 | D34: =COUNTIFS(RTM!G4:G51,"*Phase 15*",RTM!L4:L51,"Complete") -> 2 | E34: =IFERROR(D34/C34,0) -> 0.4
B35: Phase 16 | C35: =COUNTIF(RTM!G4:G51,"*Phase 16*") -> 1 | D35: =COUNTIFS(RTM!G4:G51,"*Phase 16*",RTM!L4:L51,"Complete") -> 0 | E35: =IFERROR(D35/C35,0) -> 0

Sheet RTM
A1: CrowdFix Nepal — Requirements Traceability Matrix
A2: Update Status / Test Case ID / Last Updated / Notes columns as work progresses. The Dashboard sheet recomputes automatically.
A3: Req ID | B3: Module | C3: Requirement Description | D3: Priority | E3: SRS § | F3: Design Artifact | G3: Build Phase | H3: Owner | I3: Backend Component | J3: Frontend Component | K3: Test Case ID | L3: Status | M3: Last Updated | N3: Notes
A4: FR-01 | B4: Authentication | C4: The system shall allow users to register using email/password or OAuth (Google, Facebook) | D4: High | E4: 4.1 | F4: UC-Register; Seq 7.3 | G4: Phase 4 | H4: Pratik + Anjali | I4: POST /api/auth/register; authController.register | J4: RegisterPage.jsx; AuthContext | L4: Complete | M4: 2026-06-11 | N4: POST /api/auth/register live and tested on crowdfix-frontend.vercel.app June 2026
A5: FR-02 | B5: Authentication | C5: The system shall validate email addresses via a verification link before activating accounts | D5: High | E5: 4.1 | F5: UC-Register; Seq 7.3 | G5: Phase 4 | H5: Pratik + Anjali | I5: GET /api/auth/verify; emailService.sendVerification | J5: VerifyEmailPage.jsx | L5: In Progress | M5: 2026-06-11 | N5: GET /api/auth/verify built Phase 4; email check bypassed for deployment demo; fix verify URL pending
A6: FR-03 | B6: Authentication | C6: The system shall enforce password hashing (bcrypt, min. cost factor 10) | D6: High | E6: 4.1 | F6: Security spec | G6: Phase 4 | H6: Pratik | I6: authService.hashPassword (bcrypt cost=10) | J6: — | L6: Complete | M6: 46177 | N6: bcrypt cost=10 implemented in Phase 4
A7: FR-04 | B7: Authentication | C7: The system shall support password reset via email OTP | D7: High | E7: 4.1 | F7: UC-ResetPassword | G7: Phase 4 | H7: Pratik + Anjali | I7: POST /api/auth/forgot-password; POST /api/auth/reset-password | J7: ForgotPasswordPage.jsx; ResetPasswordPage.jsx | L7: Complete | M7: 2026-06-11 | N7: forgot-password + reset-password built in Phase 4
A8: FR-05 | B8: Authentication | C8: The system shall allow users to update their profile name, photo, and contact details | D8: Medium | E8: 4.1 | F8: UC-EditProfile | G8: Phase 4 | H8: Pratik + Anjali | I8: PATCH /api/users/me; userController.updateProfile | J8: ProfilePage.jsx | L8: Not Started | M8: 2026-06-11 | N8: Profile page not linked — clicking username in sidebar does nothing; PATCH /api/users/me not implemented
A9: FR-06 | B9: Authentication | C9: Admin shall be able to deactivate or ban user accounts | D9: Medium | E9: 4.1 | F9: UC-ManageUsers | G9: Phase 11 | H9: Pratik + Anjali | I9: PATCH /api/admin/users/:id/status (role-gated) | J9: AdminUsersPage.jsx | L9: Complete | M9: 2026-06-11 | N9: Admin user deactivation implemented; role-gated endpoint
A10: FR-07 | B10: Report Submission | C10: The system shall allow users to submit a report with title, category, description, photo(s), and location | D10: High | E10: 4.2 | F10: UC-SubmitReport; Seq 7.1 | G10: Phase 7 | H10: Pratik + Anjali | I10: POST /api/reports (multer + validation) | J10: NewReportPage.jsx; ReportForm.jsx | L10: Complete | M10: 2026-06-11 | N10: NewReportPage.jsx + POST /api/reports live on Vercel+Render; tested in deployment
A11: FR-08 | B11: Report Submission | C11: The system shall auto-detect the user's GPS coordinates and allow manual adjustment on a map | D11: High | E11: 4.2 | F11: UC-SubmitReport | G11: Phase 7 | H11: Anjali | I11: — | J11: LocationPicker.jsx (Leaflet + Geolocation API) | L11: Complete | M11: 2026-06-11 | N11: GPS geolocation confirmed working in live deployment June 2026
A12: FR-09 | B12: Report Submission | C12: The system shall support categories: Infrastructure, Sanitation, Public Safety, Utilities, Environment, Other | D12: High | E12: 4.2 | F12: ER: Report.category enum | G12: Phase 2 + 7 | H12: Pratik + Umang + Anjali | I12: Prisma enum ReportCategory; validation middleware | J12: CategorySelect.jsx | L12: Complete | M12: 2026-06-11 | N12: Prisma enum ReportCategory implemented in Phase 2
A13: FR-10 | B13: Report Submission | C13: The system shall allow up to 5 photos per report, each up to 10 MB | D13: Medium | E13: 4.2 | F13: Constraint 3.5 | G13: Phase 7 | H13: Pratik + Anjali | I13: multer fileFilter + size limit; Cloudinary upload | J13: PhotoUploader.jsx (max 5, 10MB validation) | L13: Complete | M13: 2026-06-11 | N13: Photo upload with multer + Cloudinary; up to 5 photos 10MB limit
A14: FR-11 | B14: Report Submission | C14: The system shall assign a unique report ID and timestamp upon submission | D14: High | E14: 4.2 | F14: ER: Report.id, Report.createdAt | G14: Phase 2 + 7 | H14: Umang + Pratik | I14: Prisma cuid() default; createdAt @default(now()) | J14: — | L14: Complete | M14: 2026-06-11 | N14: Prisma cuid() + createdAt @default(now()) in Phase 2
A15: FR-12 | B15: Report Submission | C15: The system shall allow draft saving for offline submissions | D15: Low | E15: 4.2 | F15: — | G15: Phase 7 (defer to mobile) | H15: Anjali | I15: — | J15: Draft localStorage; mark as out-of-web-scope | L15: Not Started | M15: 2026-06-11
A16: FR-13 | B16: Report Submission | C16: The system shall allow the reporter to edit a report within 30 minutes of submission | D16: Medium | E16: 4.2 | F16: UC-EditReport | G16: Phase 7 | H16: Pratik + Anjali | I16: PATCH /api/reports/:id (time-window check) | J16: EditReportPage.jsx | L16: Complete | M16: 2026-06-11 | N16: PATCH /api/reports/:id with 30-min time-window check; EditReportPage.jsx built
A17: FR-14 | B17: Upvotes & Comments | C17: The system shall allow registered users to upvote any report (one upvote per user per report) | D17: High | E17: 4.3 | F17: ER: Upvote (userId+reportId unique) | G17: Phase 9 | H17: Pratik + Anjali | I17: POST /api/reports/:id/upvote; unique constraint | J17: UpvoteButton.jsx (optimistic update) | L17: Complete | M17: 2026-06-11 | N17: Upvote API + UI built Phase 9; unique constraint enforced
A18: FR-15 | B18: Upvotes & Comments | C18: The system shall allow users to retract their upvote | D18: Medium | E18: 4.3 | F18: ER: Upvote | G18: Phase 9 | H18: Pratik + Anjali | I18: DELETE /api/reports/:id/upvote | J18: UpvoteButton.jsx (toggle) | L18: Complete | M18: 2026-06-11 | N18: Upvote retract DELETE /api/reports/:id/upvote built
A19: FR-16 | B19: Upvotes & Comments | C19: The system shall allow registered users to post text comments on any report | D19: Medium | E19: 4.3 | F19: ER: Comment | G19: Phase 9 | H19: Pratik + Anjali | I19: POST /api/reports/:id/comments | J19: CommentForm.jsx; CommentThread.jsx | L19: Complete | M19: 2026-06-11 | N19: Comments POST /api/reports/:id/comments + CommentThread.jsx built
A20: FR-17 | B20: Upvotes & Comments | C20: The system shall allow comment authors to delete their own comments | D20: Low | E20: 4.3 | F20: ER: Comment.userId | G20: Phase 9 | H20: Pratik + Anjali | I20: DELETE /api/comments/:id (ownership check) | J20: CommentItem.jsx delete action | L20: Complete | M20: 2026-06-11 | N20: Comment delete with ownership check built
A21: FR-18 | B21: Upvotes & Comments | C21: The system shall allow admins to moderate and remove inappropriate comments | D21: High | E21: 4.3 | F21: UC-Moderate | G21: Phase 11 | H21: Pratik + Anjali | I21: DELETE /api/admin/comments/:id (role-gated) | J21: AdminModerationPage.jsx | L21: Complete | M21: 2026-06-11 | N21: Admin comment moderation endpoint built Phase 11
A22: FR-19 | B22: Status Lifecycle | C22: The system shall support report lifecycle statuses: Open, Assigned, In Progress, Resolved, Closed | D22: High | E22: 4.4 | F22: ER: Report.status enum | G22: Phase 2 + 11 | H22: Umang + Anjali | I22: Prisma enum ReportStatus; state-machine validator | J22: StatusPill.jsx | L22: Complete | M22: 2026-06-11 | N22: Prisma enum ReportStatus implemented in Phase 2
A23: FR-20 | B23: Status Lifecycle | C23: Municipal authorities shall be able to update report status from their dashboard | D23: High | E23: 4.4 | F23: UC-UpdateStatus; Seq 7.2 | G23: Phase 11 | H23: Pratik + Anjali | I23: PATCH /api/reports/:id/status (authority role) | J23: DashboardPage.jsx; StatusUpdateModal.jsx | L23: Complete | M23: 2026-06-11 | N23: Authority status update PATCH /api/reports/:id/status + StatusUpdateModal.jsx built
A24: FR-21 | B24: Status Lifecycle | C24: Authorities may attach resolution notes and photos when marking a report as Resolved | D24: Medium | E24: 4.4 | F24: ER: Report.resolutionNote, Media | G24: Phase 11 | H24: Pratik + Anjali | I24: PATCH /api/reports/:id (resolution payload) | J24: ResolveReportModal.jsx | L24: Complete | M24: 2026-06-11 | N24: Resolution notes + photo on Resolved built Phase 11
A25: FR-22 | B25: Status Lifecycle | C25: The original reporter shall be notified of every status change via push and/or email notification | D25: High | E25: 4.4 | F25: UC-NotifyUser | G25: Phase 12 | H25: Pratik + Anjali | I25: notificationService.onStatusChange; Nodemailer | J25: NotificationsPage.jsx; UnreadBadge.jsx | L25: Complete | M25: 2026-06-11 | N25: NotificationsPage.jsx + notification service built Phase 12
A26: FR-23 | B26: Status Lifecycle | C26: The system shall automatically close reports Resolved for more than 7 days without dispute | D26: Low | E26: 4.4 | F26: Scheduled job | G26: Phase 15 (defer) | H26: Pratik | I26: cron job: closeStaleResolvedReports() | J26: — | L26: Complete | M26: 2026-06-11 | N26: Auto-close cron job implemented Phase 15
A27: FR-24 | B27: Map View | C27: The system shall display all Open and In Progress reports on an interactive map | D27: High | E27: 4.5 | F27: UC-ViewMap | G27: Phase 10 | H27: Dol Bahadur | I27: GET /api/reports?status=Open,InProgress | J27: MapPage.jsx (react-leaflet) | L27: Complete | M27: 2026-06-11 | N27: MapPage.jsx with react-leaflet + OSM confirmed live on crowdfix-frontend.vercel.app June 2026
... A34: FR-31 | B34: Authority Dashboard | C34: Authorities shall be able to export reports as CSV or PDF | D34: Low | E34: 4.6 | F34: — | G34: Phase 11 | H34: Pratik + Anjali | I34: GET /api/authority/export?format=csv|pdf (papaparse, pdfkit) | J34: ExportButton.jsx | L34: Complete | M34: 2026-06-11 | N34: CSV/PDF export built Phase 11
A35: NFR-01 | B35: Performance | C35: The system shall support at least 1,000 concurrent users without degradation | D35: High | E35: 5.1 | F35: Architecture; load test | G35: Phase 13/15 | H35: Pratik | I35: Connection pooling; Render autoscale | J35: — | L35: Not Started
A36: NFR-02 | B36: Performance | C36: API responses shall be delivered within 2 seconds under normal load (95th percentile) | D36: High | E36: 5.1 | F36: Architecture | G36: Phase 13/15 | H36: Pratik | I36: DB indexes; query optimization; caching | J36: — | L36: Not Started
A37: NFR-03 | B37: Performance | C37: Map tile rendering shall complete within 3 seconds on a 4G connection | D37: Medium | E37: 5.1 | F37: — | G37: Phase 10/13 | H37: Dol Bahadur | I37: — | J37: OSM tile caching; pin clustering | L37: Not Started
A38: NFR-04 | B38: Security | C38: All data in transit shall be encrypted using TLS 1.2 or higher | D38: High | E38: 5.2 | F38: Deployment spec | G38: Phase 15 | H38: Pratik | I38: HTTPS on Render/Vercel (auto-managed) | J38: — | L38: Complete | M38: 2026-06-11 | N38: HTTPS auto-managed by Vercel (frontend) and Render (backend); confirmed live June 2026
A39: NFR-05 | B39: Security | C39: Passwords shall be hashed with bcrypt with a minimum cost factor of 10 | D39: High | E39: 5.2 | F39: Same as FR-03 | G39: Phase 4 | H39: Pratik | I39: bcrypt.hash(pwd, 10) | J39: — | L39: Complete | M39: 46181 | N39: bcrypt cost=10 confirmed in auth service Phase 4
A40: NFR-06 | B40: Security | C40: The system shall implement JWT-based stateless authentication with 1-hour expiry | D40: High | E40: 5.2 | F40: Auth middleware | G40: Phase 4 | H40: Pratik + Anjali | I40: jsonwebtoken sign w/ expiresIn:'1h'; authMiddleware | J40: axios interceptor (token refresh on 401) | L40: Complete | M40: 2026-06-11 | N40: JWT 1h expiry + axios interceptor implemented Phase 4+6
A41: NFR-07 | B41: Security | C41: The system shall implement rate limiting: max 100 API requests per minute per user | D41: High | E41: 5.2 | F41: Middleware | G41: Phase 3 | H41: Pratik | I41: express-rate-limit middleware | J41: — | L41: Complete | M41: 2026-06-11 | N41: express-rate-limit middleware confirmed in app.js; deployed to Render June 2026
A42: NFR-08 | B42: Security | C42: User location data shall never be exposed at street-level precision on the public map | D42: High | E42: 5.2 | F42: Map view spec | G42: Phase 10 | H42: Dol Bahadur | I42: Coordinate fuzzing service (~50m radius) | J42: MapPage.jsx uses fuzzed coords | L42: Not Started
A43: NFR-09 | B43: Reliability | C43: The system shall maintain 99.5% uptime measured monthly | D43: High | E43: 5.3 | F43: Deployment SLA | G43: Phase 15 | H43: Pratik | I43: Render free tier monitoring; health checks | J43: — | L43: In Progress | M43: 2026-06-11 | N43: Render free tier deployed; uptime monitoring not yet configured
A44: NFR-10 | B44: Reliability | C44: The system shall perform automated database backups every 24 hours | D44: High | E44: 5.3 | F44: — | G44: Phase 15 | H44: Pratik | I44: Render PostgreSQL daily backup (built-in) | J44: — | L44: Not Started
A45: NFR-11 | B45: Reliability | C45: Recovery Time Objective (RTO) shall be less than 4 hours | D45: Medium | E45: 5.3 | F45: — | G45: Phase 15 | H45: Pratik | I45: Documented restore runbook | J45: — | L45: Not Started
A46: NFR-12 | B46: Usability | C46: New users shall be able to submit their first report within 5 minutes without training | D46: High | E46: 5.4 | F46: Mockup UX | G46: Phase 5-7 | H46: Anjali + Dol Bahadur | I46: — | J46: Onboarding flow; minimal required fields | L46: Complete | M46: 2026-06-11 | N46: Onboarding + report form usability complete; users can submit in <5min
...

Sheet Legend
A1: How to use this RTM
A3: What is a Requirements Traceability Matrix?
A4: An RTM links each requirement from the SRS to (1) the design artifact that covers it, (2) the code/component that implements it, (3) the test case that verifies it, and (4) its current status. It's the single source of truth for 'is this project actually delivering what the SRS promised?' — and the document the professor / project committee uses to grade requirement coverage.
A6: Column glossary
A7: Column | B7: Meaning | C7: How to update
A8: Req ID | B8: Matches the SRS exactly (FR-01 .. FR-31, NFR-01 .. NFR-17). | C8: Do not edit. If a new requirement is added to the SRS, add a new row.
A9: Module | B9: Feature area (Authentication, Report Submission, etc.). | C9: Set once.
A10: Requirement Description | B10: Verbatim wording from SRS §4 / §5. | C10: Update only if SRS text changes.
A11: Priority | B11: High / Medium / Low — from SRS priority column. | C11: Dropdown. Change if priorities shift.
A12: SRS § | B12: Section number in the SRS where the requirement lives. | C12: Set once.
A13: Design Artifact | B13: Use case, sequence diagram, or ER entity that designs the requirement. | C13: Update as new diagrams are added.
A14: Build Phase | B14: Roadmap phase that will implement the requirement. | C14: Re-plan if scheduling changes.
A15: Owner | B15: Teammate(s) responsible. | C15: Dropdown. Reassign as needed.
A16: Backend Component | B16: Route / controller / service that implements the requirement on the server. | C16: Fill in as code lands.
A17: Frontend Component | B17: React page or component that surfaces the requirement to the user. | C17: Fill in as code lands.
A18: Test Case ID | B18: Identifier of the test that proves the requirement works (e.g. TC-AUTH-01). | C18: QA fills in during Phase 13.
... A21: Notes | B21: Anything else — risks, decisions, blockers, links to PRs. | C21: Free text.
A24: Status color coding
A25: Not Started | B25: Default — work has not begun.
A26: In Progress | B26: Actively being built. Owner is heads-down on it now.
A27: Complete | B27: Built, tested, merged to dev, ticked off the SRS.
A28: Blocked | B28: Cannot proceed — dependency missing / decision pending.
A29: Deferred | B29: Consciously pushed to a later phase or out of scope.
A32: Update protocol — how the team keeps this alive
A33: 1. Whenever someone starts work on a requirement, they flip its Status to 'In Progress' and set Last Updated to today.
A34: 2. When code lands on the dev branch, the implementer fills in Backend Component / Frontend Component with the actual file paths.
A35: 3. QA (Umang) assigns a Test Case ID once a test exists.
A36: 4. When a feature is merged + tested + reviewed, Status → 'Complete'. The Dashboard's % Complete ticks up automatically.
A37: 5. If anything blocks progress, flip to 'Blocked' and note the dependency in the Notes column. Bring it up at the next standup.
A38: 6. Commit the updated RTM to docs/ at every checkpoint: 'docs(rtm): update status after Phase N'.
